<?xml version="1.0" encoding="utf-8"?>
<robot xmlns:xacro="http://www.ros.org/wiki/xacro">
<!-- This URDF was automatically created by SolidWorks to URDF Exporter! Originally created by Stephen Brawner (brawner@gmail.com) 
     Commit Version: 1.6.0-4-g7f85cfe  Build Version: 1.6.7995.38578
     For more information, please see http://wiki.ros.org/sw_urdf_exporter -->
<xacro:macro name="epos2" params="parent *origin">
  <joint name="epos2_fixed" type="fixed">
	    <xacro:insert_block name="origin" />
	    <parent link="${parent}"/>
	    <child link="base_link"/>
	  </joint>

    <link
    name="base_link">
    <inertial>
      <origin
        xyz="-6.07153216591882E-18 -1.38777878078145E-17 0.005"
        rpy="0 0 0" />
      <mass
        value="0.0992146018366027" />
      <inertia
        ixx="8.41552129434506E-05"
        ixy="1.11669786591442E-20"
        ixz="-1.64881251002986E-22"
        iyy="8.41552129434506E-05"
        iyz="-1.20530670953827E-21"
        izz="0.000166656849189625" />
    </inertial>
    <visual>
      <origin
        xyz="0 0 0"
        rpy="0 0 0" />
      <geometry>
        <mesh
          filename="package://epos2_description/meshes/base_link.STL" />
      </geometry>
      <material
        name="">
        <color
          rgba="0.792156862745098 0.819607843137255 0.933333333333333 1" />
      </material>
    </visual>
    <collision>
      <origin
        xyz="0 0 0"
        rpy="0 0 0" />
      <geometry>
        <mesh
          filename="package://epos2_description/meshes/base_link.STL" />
      </geometry>
    </collision>
  </link>
  <link
    name="link1">
    <inertial>
      <origin
        xyz="-9.98000391198191E-05 -1.64798946987871E-05 -0.02"
        rpy="0 0 0" />
      <mass
        value="0.152166528796788" />
      <inertia
        ixx="6.74251545079364E-05"
        ixy="2.39074631115978E-08"
        ixz="-3.05481497149598E-22"
        iyy="6.72843219263299E-05"
        iyz="2.32785406011549E-20"
        izz="9.41317354217895E-05" />
    </inertial>
    <visual>
      <origin
        xyz="0 0 0"
        rpy="0 0 0" />
      <geometry>
        <mesh
          filename="package://epos2_description/meshes/link1.STL" />
      </geometry>
      <material
        name="">
        <color
          rgba="0.792156862745098 0.819607843137255 0.933333333333333 1" />
      </material>
    </visual>
    <collision>
      <origin
        xyz="0 0 0"
        rpy="0 0 0" />
      <geometry>
        <mesh
          filename="package://epos2_description/meshes/link1.STL" />
      </geometry>
    </collision>
  </link>
  <joint
    name="joint_1"
    type="revolute">
    <origin
      xyz="0 0 0.01"
      rpy="0 0 0.0914781903857091" />
    <parent
      link="base_link" />
    <child
      link="link1" />
    <axis
      xyz="0 0 0" />
	    <limit
	      lower="-3.14"
	      upper="3.14"
	      effort="1000"
        velocity="6.5" />
      <dynamics damping="0.7"/>
  </joint>
  </xacro:macro>
</robot>

